<?xml version="1.0" ?>
<robot name="p600_2">
  <joint name="p600__imu_joint" type="fixed">
    <parent link="p600__base_link"/>
    <child link="p600__imu_link"/>
    <origin xyz="0 0 0.205" rpy="0 0 0"/>
    <axis xyz="1 0 0"/>
    <limit lower="0.0" upper="0.0" effort="0.0" velocity="0.0"/>
  </joint>
  <joint name="p600__rotor_0_joint" type="continuous">
    <parent link="p600__base_link"/>
    <child link="p600__rotor_0"/>
    <origin xyz="0.21213 -0.21213  0.243" rpy="0 0 0"/>
    <axis xyz="0 0 1"/>
  </joint>
  <joint name="p600__rotor_1_joint" type="continuous">
    <parent link="p600__base_link"/>
    <child link="p600__rotor_1"/>
    <origin xyz="-0.21213  0.21213  0.243" rpy="0 0 0"/>
    <axis xyz="0 0 1"/>
  </joint>
  <joint name="p600__rotor_2_joint" type="continuous">
    <parent link="p600__base_link"/>
    <child link="p600__rotor_2"/>
    <origin xyz="0.21213 0.21213 0.243" rpy="0 0 0"/>
    <axis xyz="0 0 1"/>
  </joint>
  <joint name="p600__rotor_3_joint" type="continuous">
    <parent link="p600__base_link"/>
    <child link="p600__rotor_3"/>
    <origin xyz="-0.21213 -0.21213  0.243" rpy="0 0 0"/>
    <axis xyz="0 0 1"/>
  </joint>
  <link name="p600__base_link">
    <inertial>
      <mass value="3.0"/>
      <origin xyz="-0.015 0 0.175" rpy="0 0 0"/>
      <inertia ixx="0.05487" ixy="0" ixz="0" iyy="0.05487" iyz="0" izz="0.1027"/>
    </inertial>
    <collision name="p600__base_link_inertia_collision">
      <origin xyz="0 0 0" rpy="0 0 0"/>
      <geometry>
        <mesh filename="meshes/p600_lq.stl" scale="1 1 1"/>
      </geometry>
    </collision>
    <visual name="p600__base_link_inertia_visual">
      <origin xyz="0 0 0" rpy="0 0 0"/>
      <geometry>
        <mesh filename="meshes/p600_lq.stl" scale="1 1 1"/>
      </geometry>
    </visual>
  </link>
  <link name="p600__imu_link">
    <inertial>
      <mass value="0.015"/>
      <origin xyz="0 0 0" rpy="0 0 0"/>
      <inertia ixx="1e-05" ixy="0" ixz="0" iyy="1e-05" iyz="0" izz="1e-05"/>
    </inertial>
  </link>
  <link name="p600__rotor_0">
    <inertial>
      <mass value="0.005"/>
      <origin xyz="0 0 0" rpy="0 0 0"/>
      <inertia ixx="9.75e-07" ixy="0" ixz="0" iyy="0.000273104" iyz="0" izz="0.000274004"/>
    </inertial>
    <collision name="p600__rotor_0_collision">
      <origin xyz="0 0 0" rpy="0 0 0"/>
      <geometry>
        <cylinder radius="0.128" length="0.005"/>
      </geometry>
    </collision>
    <visual name="p600__rotor_0_visual">
      <origin xyz="0 0 0" rpy="0 0 0"/>
      <geometry>
        <mesh filename="meshes/p600_ccw_lq.stl" scale="1 1 1"/>
      </geometry>
    </visual>
  </link>
  <link name="p600__rotor_1">
    <inertial>
      <mass value="0.005"/>
      <origin xyz="0 0 0" rpy="0 0 0"/>
      <inertia ixx="9.75e-07" ixy="0" ixz="0" iyy="0.000273104" iyz="0" izz="0.000274004"/>
    </inertial>
    <collision name="p600__rotor_1_collision">
      <origin xyz="0 0 0" rpy="0 0 0"/>
      <geometry>
        <cylinder radius="0.128" length="0.005"/>
      </geometry>
    </collision>
    <visual name="p600__rotor_1_visual">
      <origin xyz="0 0 0" rpy="0 0 0"/>
      <geometry>
        <mesh filename="meshes/p600_ccw_lq.stl" scale="1 1 1"/>
      </geometry>
    </visual>
  </link>
  <link name="p600__rotor_2">
    <inertial>
      <mass value="0.005"/>
      <origin xyz="0 0 0" rpy="0 0 0"/>
      <inertia ixx="9.75e-07" ixy="0" ixz="0" iyy="0.000273104" iyz="0" izz="0.000274004"/>
    </inertial>
    <collision name="p600__rotor_2_collision">
      <origin xyz="0 0 0" rpy="0 0 0"/>
      <geometry>
        <cylinder radius="0.128" length="0.005"/>
      </geometry>
    </collision>
    <visual name="p600__rotor_2_visual">
      <origin xyz="0 0 0" rpy="0 0 0"/>
      <geometry>
        <mesh filename="meshes/p600_cw_lq.stl" scale="1 1 1"/>
      </geometry>
    </visual>
  </link>
  <link name="p600__rotor_3">
    <inertial>
      <mass value="0.005"/>
      <origin xyz="0 0 0" rpy="0 0 0"/>
      <inertia ixx="9.75e-07" ixy="0" ixz="0" iyy="0.000273104" iyz="0" izz="0.000274004"/>
    </inertial>
    <collision name="p600__rotor_3_collision">
      <origin xyz="0 0 0" rpy="0 0 0"/>
      <geometry>
        <cylinder radius="0.128" length="0.005"/>
      </geometry>
    </collision>
    <visual name="p600__rotor_3_visual">
      <origin xyz="0 0 0" rpy="0 0 0"/>
      <geometry>
        <mesh filename="meshes/p600_cw_lq.stl" scale="1 1 1"/>
      </geometry>
    </visual>
  </link>
</robot>
