<?xml version="1.0" ?>
<robot name="rotor">


  <joint name="p600__rotor_0_joint" type="continuous">
    <parent link="world"/>
    <child link="p600__rotor_0"/>
     <origin xyz="0 0 0" rpy="0 0 0"/>
    <axis xyz="0 0 1"/>
  </joint>
  

  <link name="world"/>
  <link name="p600__rotor_0">
    <inertial>
      <mass value="0.005"/>
      <origin xyz="0 0 0" rpy="0 0 0"/>
      <inertia ixx="9.75e-07" ixy="0" ixz="0" iyy="0.000273104" iyz="0" izz="0.000274004"/>
    </inertial>
    <collision name="p600__rotor_0_collision">
      <origin xyz="0 0 0" rpy="0 0 0"/>
      <geometry>
        <cylinder radius="0.128" length="0.005"/>
      </geometry>
    </collision>
    <visual name="p600__rotor_0_visual">
      <origin xyz="0 0 0" rpy="0 0 0"/>
      <geometry>
        <mesh filename="meshes/p600_ccw_lq.stl" scale="1 1 1"/>
      </geometry>
    </visual>
  </link>

</robot>
